Workbook

Sheet README
A1: ◆ MĀLAMA LABS
A2: Pro Forma v2.0
A3: Aligned to the published V1 document set · launch.malamalabs.com/docs · June 2026
A6: PURPOSE
A7: This pro forma models Mālama Labs financials from the canonical V1 economics
A8: published at launch.malamalabs.com/docs. Every structural input ties to a
A9: published source. Revenue is presented as scenario estimates, explicitly
A10: labeled, never as commitments or distribution guidance.
A12: CANONICAL INPUTS (published, not assumed)
A13: Entry price per Hex Node | D13: $2,000 (one-time)
A14: — Hardware component | D14: $380
A15: — Geographic hex license | D15: $1,620
A16: Genesis 200 structure | D16: 195 external + 5 reserved
A17: Genesis external raise | D17: $390,000
A18: Hardware ships | D18: End December 2026
A19: Mainnet target | D19: Q4 2026
A20: MLMA per operator | D20: 125,000 (service-conditional)
A21: Token hard cap | D21: 500,000,000 MLMA
A22: Emissions | D22: 60M over 8-yr taper (12/14/12/9/6/4/2/1M)
A23: Revenue split | D23: 45 burn / 20 operators / 15 stakers / 20 Foundation
A24: Burn floor | D24: 250M circulating
A26: REVENUE ARCHITECTURE (per Validator Fees v0.1, DOCS-07)
A27: Protocol revenue is USDC paid by commercial buyers of hardware-signed data
A28: across nine verticals. Mālama operates the commercial relationships and the
A29: network; operators receive validator-fee distributions. The pro forma models
A30: Mālama's retained protocol revenue plus the hex-license and hardware margin.
A32: NINE VERTICALS (independent demand drivers)
A33: Carbon dMRV · AI compute emissions · energy/grid licensing · parametric
A34: insurance · EUDR supply chain · prediction-market oracle · smart agriculture
A35: · Smart City/grid · LCO₂/VCO₂ settlement
A37: TABS
A38: Assumptions | D38: All scenario inputs (blue = editable)
A39: Node_Rollout | D39: Node deployment by cohort and year
A40: Validator_Fees | D40: USDC commercial revenue build, per DOCS-07
A41: Revenue_Build | D41: Mālama retained revenue, three lines
A42: P&L | D42: Five-year P&L, three scenarios
A43: Use_of_Funds | D43: Seed deployment
A44: Scenarios | D44: Bear / Base / Bull summary + valuation
A46: STAGE-HONESTY
A47: Settlement and validator-fee revenue is nascent during the Genesis period.
...

Sheet Assumptions
A1: ◆ MĀLAMA LABS
A2: Assumptions
A3: Blue = editable input. Black = derived. Change scenario drivers here.
A5: Driver | B5: Bear | C5: Base | D5: Bull | E5: Unit / Source
A6: CANONICAL — fixed (published)
A7: Entry price per node | B7: 2000 | C7: 2000 | D7: 2000 | E7: $ · DOCS-02
A8: Hardware cost in price | B8: 380 | C8: 380 | D8: 380 | E8: $ · DOCS-02
A9: Hex license in price | B9: 1620 | C9: 1620 | D9: 1620 | E9: $ · DOCS-02
A10: Hardware COGS per node | B10: 300 | C10: 285 | D10: 270 | E10: $ · est. landed
A11: Genesis external nodes | B11: 195 | C11: 195 | D11: 195 | E11: # · DOCS-02
A13: NODE ROLLOUT — scenario
A14: Genesis Yr1 (2026) nodes | B14: 195 | C14: 195 | D14: 195 | E14: # cumulative
A15: Yr2 (2027) nodes | B15: 600 | C15: 1200 | D15: 2000 | E15: # cumulative
A16: Yr3 (2028) nodes | B16: 1500 | C16: 3500 | D16: 6000 | E16: # cumulative
A17: Yr4 (2029) nodes | B17: 3500 | C17: 8000 | D17: 14000 | E17: # cumulative
A18: Yr5 (2030) nodes | B18: 7000 | C18: 16000 | D18: 28000 | E18: # cumulative
A20: VALIDATOR FEES — scenario
A21: Monthly USDC rev / active node Yr1 | B21: 40 | C21: 60 | D21: 90 | E21: $ · DOCS-07 ex.
A22: Monthly USDC rev / active node Yr3 | B22: 120 | C22: 200 | D22: 320 | E22: $ · scenario
A23: Monthly USDC rev / active node Yr5 | B23: 260 | C23: 420 | D23: 650 | E23: $ · scenario
A24: Mālama protocol take of gross rev | B24: 0.3 | C24: 0.35 | D24: 0.4 | E24: % · operator split net
A26: OPEX — scenario
A27: Team headcount Yr1 | B27: 8 | C27: 8 | D27: 8 | E27: # FTE
A28: Team headcount Yr5 | B28: 25 | C28: 40 | D28: 60 | E28: # FTE
A29: Avg fully-loaded cost / FTE | B29: 165000 | C29: 175000 | D29: 185000 | E29: $ / yr
A30: Non-payroll opex % of revenue | B30: 0.35 | C30: 0.3 | D30: 0.25 | E30: %
A32: VALUATION
A33: Exit revenue multiple | B33: 10 | C33: 12 | D33: 15 | E33: x · DePIN comps

Sheet Node_Rollout
A1: ◆ MĀLAMA LABS
A2: Node Rollout
A3: Cumulative deployed nodes by scenario. New nodes drive license + hardware revenue.
A5: Scenario | B5: 2026 (Gen) | C5: 2027 | D5: 2028 | E5: 2029 | F5: 2030
A6: Bear — cumulative | B6: =Assumptions!B14 -> 195 | C6: =Assumptions!B15 -> 600 | D6: =Assumptions!B16 -> 1500 | E6: =Assumptions!B17 -> 3500 | F6: =Assumptions!B18 -> 7000
A7: Base — cumulative | B7: =Assumptions!C14 -> 195 | C7: =Assumptions!C15 -> 1200 | D7: =Assumptions!C16 -> 3500 | E7: =Assumptions!C17 -> 8000 | F7: =Assumptions!C18 -> 16000
A8: Bull — cumulative | B8: =Assumptions!D14 -> 195 | C8: =Assumptions!D15 -> 2000 | D8: =Assumptions!D16 -> 6000 | E8: =Assumptions!D17 -> 14000 | F8: =Assumptions!D18 -> 28000
A10: NEW NODES / YEAR (Base)
A11: New nodes (Base) | B11: =B7 -> 195 | C11: =C7-B7 -> 1005 | D11: =D7-C7 -> 2300 | E11: =E7-D7 -> 4500 | F11: =F7-E7 -> 8000

Sheet Validator_Fees
A1: ◆ MĀLAMA LABS
A2: Validator Fees
A3: Gross USDC commercial revenue (DOCS-07). Per-node monthly fee × active nodes × 12.
A5: Line (Base case) | B5: 2026 (Gen) | C5: 2027 | D5: 2028 | E5: 2029 | F5: 2030
A6: Monthly USDC / active node | B6: =Assumptions!C21 -> 60 | C6: =(Assumptions!C21+Assumptions!C22)/2 -> 130 | D6: =Assumptions!C22 -> 200 | E6: =(Assumptions!C22+Assumptions!C23)/2 -> 310 | F6: =Assumptions!C23 -> 420
A7: Active nodes (Base, cumulative) | B7: =Node_Rollout!B7 -> 195 | C7: =Node_Rollout!C7 -> 1200 | D7: =Node_Rollout!D7 -> 3500 | E7: =Node_Rollout!E7 -> 8000 | F7: =Node_Rollout!F7 -> 16000
A8: Gross USDC validator revenue | B8: =B6*B7*12*0.55 -> 77220 | C8: =C6*C7*12*0.8 -> 1497600 | D8: =D6*D7*12*0.9 -> 7560000 | E8: =E6*E7*12*0.9 -> 26784000 | F8: =F6*F7*12*0.9 -> 72576000
A10: Ramp factor applied (deploy-year nodes partial): Yr1 0.55, Yr2 0.80, Yr3+ 0.90

Sheet Revenue_Build
A1: ◆ MĀLAMA LABS
A2: Revenue Build
A3: Mālama retained revenue (Base): protocol take + hex-license + hardware margin.
A5: Revenue line (Base, $) | B5: 2026 (Gen) | C5: 2027 | D5: 2028 | E5: 2029 | F5: 2030
A6: Protocol take (validator fees) | B6: =Validator_Fees!B8*Assumptions!C24 -> 27027 | C6: =Validator_Fees!C8*Assumptions!C24 -> 524160 | D6: =Validator_Fees!D8*Assumptions!C24 -> 2646000 | E6: =Validator_Fees!E8*Assumptions!C24 -> 9374400 | F6: =Validator_Fees!F8*Assumptions!C24 -> 25401600
A7: Hex license revenue (new nodes) | B7: =Node_Rollout!B11*Assumptions!C9 -> 315900 | C7: =Node_Rollout!C11*Assumptions!C9 -> 1628100 | D7: =Node_Rollout!D11*Assumptions!C9 -> 3726000 | E7: =Node_Rollout!E11*Assumptions!C9 -> 7290000 | F7: =Node_Rollout!F11*Assumptions!C9 -> 12960000
A8: Hardware margin (new nodes) | B8: =Node_Rollout!B11*(Assumptions!C8-Assumptions!C10) -> 18525 | C8: =Node_Rollout!C11*(Assumptions!C8-Assumptions!C10) -> 95475 | D8: =Node_Rollout!D11*(Assumptions!C8-Assumptions!C10) -> 218500 | E8: =Node_Rollout!E11*(Assumptions!C8-Assumptions!C10) -> 427500 | F8: =Node_Rollout!F11*(Assumptions!C8-Assumptions!C10) -> 760000
A9: Total Mālama revenue | B9: =SUM(B6:B8) -> 361452 | C9: =SUM(C6:C8) -> 2247735 | D9: =SUM(D6:D8) -> 6590500 | E9: =SUM(E6:E8) -> 17091900 | F9: =SUM(F6:F8) -> 39121600

Sheet P&L
A1: ◆ MĀLAMA LABS
A2: P&L — Base Case
A3: Five-year. Revenue from Revenue_Build; opex from Assumptions.
A5: ($) | B5: 2026 (Gen) | C5: 2027 | D5: 2028 | E5: 2029 | F5: 2030
A6: Revenue | B6: =Revenue_Build!B9 -> 361452 | C6: =Revenue_Build!C9 -> 2247735 | D6: =Revenue_Build!D9 -> 6590500 | E6: =Revenue_Build!E9 -> 17091900 | F6: =Revenue_Build!F9 -> 39121600
A7: Headcount (FTE) | B7: =ROUND(Assumptions!C27+(Assumptions!C28-Assumptions!C27)*0,0) -> 8 | C7: =ROUND(Assumptions!C27+(Assumptions!C28-Assumptions!C27)*0.25,0) -> 16 | D7: =ROUND(Assumptions!C27+(Assumptions!C28-Assumptions!C27)*0.5,0) -> 24 | E7: =ROUND(Assumptions!C27+(Assumptions!C28-Assumptions!C27)*0.75,0) -> 32 | F7: =ROUND(Assumptions!C27+(Assumptions!C28-Assumptions!C27)*1,0) -> 40
A8: Payroll | B8: =-B7*Assumptions!C29 -> -1400000 | C8: =-C7*Assumptions!C29 -> -2800000 | D8: =-D7*Assumptions!C29 -> -4200000 | E8: =-E7*Assumptions!C29 -> -5600000 | F8: =-F7*Assumptions!C29 -> -7000000
A9: Non-payroll opex | B9: =-B6*Assumptions!C30 -> -108435.6 | C9: =-C6*Assumptions!C30 -> -674320.5 | D9: =-D6*Assumptions!C30 -> -1977150 | E9: =-E6*Assumptions!C30 -> -5127570 | F9: =-F6*Assumptions!C30 -> -11736480
A10: EBITDA | B10: =B6+B8+B9 -> -1146983.6 | C10: =C6+C8+C9 -> -1226585.5 | D10: =D6+D8+D9 -> 413350 | E10: =E6+E8+E9 -> 6364330 | F10: =F6+F8+F9 -> 20385120
A11: EBITDA margin | B11: =IF(B6=0,0,B10/B6) -> -3.1732667 | C11: =IF(C6=0,0,C10/C6) -> -0.54569845 | D11: =IF(D6=0,0,D10/D6) -> 0.062719065 | E11: =IF(E6=0,0,E10/E6) -> 0.37235942 | F11: =IF(F6=0,0,F10/F6) -> 0.52107071

Sheet Use_of_Funds
A1: ◆ MĀLAMA LABS
A2: Use of Funds
A3: Illustrative Seed deployment. Adjust to the actual round size.
A5: Category | B5: Allocation % | C5: Notes
A6: Engineering & product | B6: 0.34 | C6: Core protocol, NodeCommand, validator-fee rails
A7: Hardware & supply chain | B7: 0.18 | C7: Genesis production, next-cohort tooling, inventory
A8: Field ops & operator success | B8: 0.14 | C8: Deployment support, PONO qualification, stewardship
A9: Commercial & partnerships | B9: 0.14 | C9: Registry, AI-compute, insurance deal origination
A10: Regulatory & legal | B10: 0.08 | C10: Securities, token, registry compliance
A11: G&A & runway buffer | B11: 0.12 | C11: Finance, ops, contingency
A12: Total | B12: =SUM(B6:B11) -> 1

Sheet Scenarios
A1: ◆ MĀLAMA LABS
A2: Scenarios
A3: Year-5 revenue and illustrative valuation across Bear / Base / Bull.
A5: Metric (Year 5) | B5: Bear | C5: Base | D5: Bull | E5: Source
A6: Cumulative nodes (Yr5) | B6: =Assumptions!B18 -> 7000 | C6: =Assumptions!C18 -> 16000 | D6: =Assumptions!D18 -> 28000 | E6: Assumptions
A7: Monthly USDC / node (Yr5) | B7: =Assumptions!B23 -> 260 | C7: =Assumptions!C23 -> 420 | D7: =Assumptions!D23 -> 650 | E7: Assumptions
A8: Gross validator rev (Yr5) | B8: =B6*B7*12*0.9 -> 19656000 | C8: =C6*C7*12*0.9 -> 72576000 | D8: =D6*D7*12*0.9 -> 196560000 | E8: nodes×fee×12×0.9
A9: Protocol take | B9: =B8*Assumptions!B24 -> 5896800 | C9: =C8*Assumptions!C24 -> 25401600 | D9: =D8*Assumptions!D24 -> 78624000 | E9: × take %
A10: Hex license (Yr5 new) | B10: =(Assumptions!B18-Assumptions!B17)*Assumptions!B9 -> 5670000 | C10: =(Assumptions!C18-Assumptions!C17)*Assumptions!C9 -> 12960000 | D10: =(Assumptions!D18-Assumptions!D17)*Assumptions!D9 -> 22680000 | E10: new×$1,620
A11: Hardware margin (Yr5 new) | B11: =(Assumptions!B18-Assumptions!B17)*(Assumptions!B8-Assumptions!B10) -> 280000 | C11: =(Assumptions!C18-Assumptions!C17)*(Assumptions!C8-Assumptions!C10) -> 760000 | D11: =(Assumptions!D18-Assumptions!D17)*(Assumptions!D8-Assumptions!D10) -> 1540000 | E11: new×margin
A12: Total Mālama rev (Yr5) | B12: =B9+B10+B11 -> 11846800 | C12: =C9+C10+C11 -> 39121600 | D12: =D9+D10+D11 -> 102844000 | E12: sum
A13: Exit multiple | B13: =Assumptions!B33 -> 10 | C13: =Assumptions!C33 -> 12 | D13: =Assumptions!D33 -> 15 | E13: Assumptions
A14: Implied valuation | B14: =B12*B13 -> 118468000 | C14: =C12*C13 -> 469459200 | D14: =D12*D13 -> 1542660000 | E14: rev×multiple
A16: All three scenarios are illustrative estimates, not commitments. Built on published V1 unit economics.
A17: Revenue is nascent during Genesis; validator-fee economics scale with commercial adoption (DOCS-07).
